<?xml version="1.0" ?>
<robot name="quadruped" xmlns:xacro="http://ros.org/wiki/xacro">
    <link name="body">
        <inertial>
            <mass value="3.5"/>
            <origin xyz="0.0 0.0 0.0"/>
            <inertia ixx="0.024" ixy="0" ixz="0" iyy="0.159" iyz="0" izz="0.173"/>
        </inertial>
        <visual>
            <geometry>
                <mesh filename="meshes/body.stl"/>
            </geometry>
            <origin rpy="0.0 0.0 0.0" xyz="0.0 0.0 0.0"/>
            <material name="g">
                <color rgba="0.54509804 0.54509804 0.47843137 1"/>
            </material>
        </visual>
        <collision>
            <geometry>
                <mesh filename="meshes/body.stl"/>
            </geometry>
            <origin rpy="0 0 0" xyz="0 0 0"/>
        </collision>
    </link>

    <!--!!!!!!!!!!!! Front Right Leg !!!!!!!!!!!!!!!!!!!!!!!!!!!!!!!!!!!!-->
    <joint name="motor_hip_frontR_j" type="continuous">
        <axis xyz="1 0 0"/>
        <origin rpy="0 0 0" xyz="0.214 -0.0725 0.0"/>
        <parent link="body"/>
        <child link="abduct_fr"/>
        <limit effort="100" velocity="100"/>
        <joint_properties damping="0.0" friction="0.0"/>
    </joint>
    <link name="abduct_fr">
        <inertial>
            <mass value="0.56"/>
            <origin xyz="0.0 0.036 0."/>
            <inertia ixx="0.000381" ixy="0.000058" ixz="0.00000045"
                iyy="0.000560" iyz="0.00000095" izz="0.000444"/>
        </inertial>
        <visual>
            <geometry>
                <mesh filename="meshes/abad.stl"/>
            </geometry>
            <material name="y">
                <color rgba="1. 0.84313725 0. 1"/>
            </material>
            <origin rpy="0 0.0 0" xyz="0 0.0 0.0"/>
        </visual>
        <collision>
            <geometry>
                <mesh filename="meshes/abad.stl"/>
            </geometry>
            <origin rpy="0 0 0" xyz="0 0 0"/>
        </collision>
    </link>

    <joint name="motor_upper_frontR_j" type="continuous">
        <axis xyz="0 1 0"/>
        <origin rpy="0.0 0.0 0.0" xyz="0.0 -0.088 0.00"/>
        <parent link="abduct_fr"/>
        <child link="thigh_fr"/>
        <limit effort="100" velocity="100"/>
        <joint_properties damping="0.0" friction="0.0"/>
    </joint>

    <link name="thigh_fr">
        <inertial>
            <mass value="0.634"/>
            <origin xyz="0.0 0.0 0.0"/>
            <inertia ixx="0.001983" ixy="0.000245" ixz="0.000013"
                iyy="0.002103" iyz="0.0000015" izz="0.000408"/>
        </inertial>
        <visual>
            <geometry>
                <mesh filename="meshes/upperleg.stl"/>
            </geometry>
            <material name="y">
                <color rgba="1. 0.84313725 0. 1"/>
            </material>
            <origin rpy="0.0 0 0.0" xyz="0.0 0.0 0.0"/>
        </visual>
        <collision>
            <geometry>
                <mesh filename="meshes/upperleg.stl"/>
            </geometry>
            <origin rpy="0 0 0" xyz="0 0 0"/>
        </collision>
    </link>

    <joint name="motor_lower_frontR_j" type="continuous">
        <axis xyz="0 1 0"/>
        <origin rpy="0.0 0 0.0" xyz="0.0 0.0 -0.3"/>
        <parent link="thigh_fr"/>
        <child link="shank_fr"/>
        <limit effort="100" velocity="100"/>
        <joint_properties damping="0.0" friction="0.0"/>
    </joint>
    <link name="shank_fr">
        <inertial>
            <mass value="0.064"/>
            <origin xyz="0.0 0.0 -0.28"/>
            <inertia ixx="0.000245" ixy="0" ixz="0.0" iyy="0.000248" iyz="0" izz="0.000006"/>
        </inertial>
        <visual>
            <geometry>
                <mesh filename="meshes/lowerleg.stl"/>
            </geometry>
            <material name="g">
                <color rgba="0.54509804 0.54509804 0.47843137 1"/>
            </material>
            <origin rpy="0.0 0 0.0" xyz="0.0 0.0 0.0"/>
        </visual>
        <collision>
            <geometry>
                <mesh filename="meshes/lowerleg.stl"/>
            </geometry>
            <origin rpy="0 0 0" xyz="0 0 0"/>
        </collision>
    </link>

    <link name="toe_fr">
    <contact>
      <friction_anchor/>
      <stiffness value="30000.0"/>
      <damping value="1000.0"/>
      <spinning_friction value="0.3"/>
      <lateral_friction value="3.0"/>
    </contact>
    <visual>
      <origin rpy="0 0 0" xyz="0 0 0"/>
      <geometry>
        <sphere radius="0.015"/>
      </geometry>
      <material name="black">
          <color rgba="1 1 1 1"/>
      </material>
    </visual>
    <collision>
      <origin rpy="0 0 0" xyz="0 0 0"/>
      <geometry>
        <sphere radius="0.015"/>
      </geometry>
    </collision>
    <inertial>
      <mass value="0.15"/>
      <inertia ixx="0.000025" ixy="0" ixz="0" iyy="0.000025" iyz="0" izz="0.000025"/>
    </inertial>
  </link>

  <joint name="toe_fr_joint" type="fixed">
    <parent link="shank_fr"/>
    <child link="toe_fr"/>
    <origin xyz="0 0 -0.28"/>
    <limit effort="100" velocity="100"/>
    <joint_properties damping="0.0" friction="0.0"/>
  </joint>


    <!--!!!!!!!!!!!! Front Left Leg !!!!!!!!!!!!!!!!!!!!!!!!!!!!!!!!!!!!-->
    <joint name="motor_hip_frontL_j" type="continuous">
        <axis xyz="1 0 0"/>
        <origin rpy="0 0 0" xyz="0.214 0.0725 0.0"/>
        <parent link="body"/>
        <child link="abduct_fl"/>
        <limit effort="100" velocity="100"/>
        <joint_properties damping="0.0" friction="0.0"/>
    </joint>
    <link name="abduct_fl">
        <inertial>
            <mass value="0.56"/>
            <origin xyz="0.0 0.036 0."/>
            <inertia ixx="0.000381" ixy="0.000058" ixz="0.00000045"
                iyy="0.000560" iyz="0.00000095" izz="0.000444"/>
        </inertial>
        <visual>
            <geometry>
                <mesh filename="meshes/abad.stl"/>
            </geometry>
            <material name="y">
                <color rgba="1. 0.84313725 0. 1"/>
            </material>
            <origin rpy="0 0.0 3.14159" xyz="0 0.0 0.0"/>
        </visual>
        <collision>
            <geometry>
                <mesh filename="meshes/abad.stl"/>
            </geometry>
            <origin rpy="0 0 3.14159" xyz="0 0 0"/>
        </collision>
    </link>

    <joint name="motor_upper_frontL_j" type="continuous">
        <axis xyz="0 1 0"/>
        <origin rpy="0.0 0.0 0.0" xyz="0.0 0.088 0.00"/>
        <parent link="abduct_fl"/>
        <child link="thigh_fl"/>
        <limit effort="100" velocity="100"/>
        <joint_properties damping="0.0" friction="0.0"/>
    </joint>

    <link name="thigh_fl">
        <inertial>
            <mass value="0.634"/>
            <origin xyz="0.0 0.0 0.0"/>
            <inertia ixx="0.001983" ixy="0.000245" ixz="0.000013"
                iyy="0.002103" iyz="0.0000015" izz="0.000408"/>
        </inertial>
        <visual>
            <geometry>
                <mesh filename="meshes/upperleg.stl"/>
            </geometry>
            <material name="y">
                <color rgba="1. 0.84313725 0. 1"/>
            </material>
            <origin rpy="0.0 0 3.14159" xyz="0.0 0.0 0.0"/>
        </visual>
        <collision>
            <geometry>
                <mesh filename="meshes/upperleg.stl"/>
            </geometry>
            <origin rpy="0 0 3.14159" xyz="0 0 0"/>
        </collision>
    </link>

    <joint name="motor_lower_frontL_j" type="continuous">
        <axis xyz="0 1 0"/>
        <origin rpy="0.0 0 0.0" xyz="0.0 0.0 -0.3"/>
        <parent link="thigh_fl"/>
        <child link="shank_fl"/>
        <limit effort="100" velocity="100"/>
        <joint_properties damping="0.0" friction="0.0"/>
    </joint>

    <link name="shank_fl">
        <inertial>
            <mass value="0.064"/>
            <origin xyz="0.0 0.0 -0.3"/>
            <inertia ixx="0.000245" ixy="0" ixz="0.0" iyy="0.000248" iyz="0" izz="0.000006"/>
        </inertial>
        <visual>
            <geometry>
                <mesh filename="meshes/lowerleg.stl"/>
            </geometry>
            <material name="g">
                <color rgba="0.54509804 0.54509804 0.47843137 1"/>
            </material>
            <origin rpy="0.0 0 0.0" xyz="0.0 0.0 0.0"/>
        </visual>
        <collision>
            <geometry>
                <mesh filename="meshes/lowerleg.stl"/>
            </geometry>
            <origin rpy="0 0 0" xyz="0 0 0"/>
        </collision>
    </link>

    <link name="toe_fl">
      <contact>
      <friction_anchor/>
      <stiffness value="30000.0"/>
      <damping value="1000.0"/>
      <spinning_friction value="0.3"/>
      <lateral_friction value="3.0"/>
    </contact>
    <visual>
      <origin rpy="0 0 0" xyz="0 0 0"/>
      <geometry>
        <sphere radius="0.015"/>
      </geometry>
        <material name="black">
          <color rgba="1 1 1 1"/>
      </material>
      <material name="darkgray"/>
    </visual>
    <collision>
      <origin rpy="0 0 0" xyz="0 0 0"/>
      <geometry>
        <sphere radius="0.015"/>
      </geometry>
    </collision>
    <inertial>
      <mass value="0.15"/>
      <inertia ixx="0.000025" ixy="0" ixz="0" iyy="0.000025" iyz="0" izz="0.000025"/>
    </inertial>
  </link>
  <joint name="toe_fl_joint" type="fixed">
    <parent link="shank_fl"/>
    <child link="toe_fl"/>
    <origin xyz="0 0 -0.28"/>
    <limit effort="100" velocity="100"/>
    <joint_properties damping="0.0" friction="0.0"/>
  </joint>


<!--!!!!!!!!!!!! Hind Right Leg !!!!!!!!!!!!!!!!!!!!!!!!!!!!!!!!!!!!-->
    <joint name="motor_hip_backR_j" type="continuous">
        <axis xyz="1 0 0"/>
        <origin rpy="0 0 0" xyz="-0.214 -0.0725 0.0"/>
        <parent link="body"/>
        <child link="abduct_hr"/>
        <limit effort="100" velocity="100"/>
        <joint_properties damping="0.0" friction="0.0"/>
    </joint>
    <link name="abduct_hr">
        <inertial>
            <mass value="0.56"/>
            <origin xyz="0.0 0 0."/>
            <inertia ixx="0.000381" ixy="0.000058" ixz="0.00000045"
                iyy="0.000560" iyz="0.00000095" izz="0.000444"/>
        </inertial>
        <visual>
            <geometry>
                <mesh filename="meshes/abad.stl"/>
            </geometry>
            <material name="y">
                <color rgba="1. 0.84313725 0. 1"/>
            </material>
            <origin rpy="0.0 0.0 0" xyz="0 0.0 0.0"/>
        </visual>
        <collision>
            <geometry>
                <mesh filename="meshes/abad.stl"/>
            </geometry>
            <origin rpy="0 0 0" xyz="0 0 0"/>
        </collision>
    </link>

    <joint name="motor_upper_backR_j" type="continuous">
        <axis xyz="0 1 0"/>
        <origin rpy="0.0 0.0 0.0" xyz="0.0 -0.088 0.00"/>
        <parent link="abduct_hr"/>
        <child link="thigh_hr"/>
        <limit effort="100" velocity="100"/>
        <joint_properties damping="0.0" friction="0.0"/>
    </joint>
    <link name="thigh_hr">
        <inertial>
            <mass value="0.634"/>
            <origin xyz="0.0 0.016 -0.02"/>
            <inertia ixx="0.001983" ixy="0.000245" ixz="0.000013"
                iyy="0.002103" iyz="0.0000015" izz="0.000408"/>
        </inertial>
        <visual>
            <geometry>
                <mesh filename="meshes/upperleg.stl"/>
            </geometry>
            <material name="y">
                <color rgba="1. 0.84313725 0. 1"/>
            </material>
            <origin rpy="0.0 0 0.0" xyz="0.0 0.0 0.0"/>
        </visual>
        <collision>
            <geometry>
                <mesh filename="meshes/upperleg.stl"/>
            </geometry>
            <origin rpy="0 0 0" xyz="0 0 0"/>
        </collision>
    </link>

    <joint name="motor_lower_backR_j" type="continuous">
        <axis xyz="0 1 0"/>
        <origin rpy="0.0 0 0.0" xyz="0.0 0.0 -0.3"/>
        <parent link="thigh_hr"/>
        <child link="shank_hr"/>
        <limit effort="100" velocity="100"/>
        <joint_properties damping="0.0" friction="0.0"/>
    </joint>
    <link name="shank_hr">
        <inertial>
            <mass value="0.064"/>
            <origin xyz="0.0 0.0 -0.3"/>
            <inertia ixx="0.000245" ixy="0" ixz="0.0" iyy="0.000248" iyz="0" izz="0.000006"/>
        </inertial>
        <visual>
            <geometry>
                <mesh filename="meshes/lowerleg.stl"/>
            </geometry>
            <material name="g">
                <color rgba="0.54509804 0.54509804 0.47843137 1"/>
            </material>
            <origin rpy="0.0 0 0.0" xyz="0.0 0.0 0.0"/>
        </visual>
        <collision>
            <geometry>
                <mesh filename="meshes/lowerleg.stl"/>
            </geometry>
            <origin rpy="0 0 0" xyz="0 0 0"/>
        </collision>
    </link>
     <link name="toe_hr">
      <contact>
      <friction_anchor/>
      <stiffness value="30000.0"/>
      <damping value="1000.0"/>
      <spinning_friction value="0.3"/>
      <lateral_friction value="3.0"/>
    </contact>
    <visual>
      <origin rpy="0 0 0" xyz="0 0 0"/>
      <geometry>
        <sphere radius="0.015"/>
      </geometry>
        <material name="black">
                <color rgba="0 0 0 1"/>
        </material>
      <material name="darkgray"/>
    </visual>
    <collision>
      <origin rpy="0 0 0" xyz="0 0 0"/>
      <geometry>
        <sphere radius="0.015"/>
      </geometry>
    </collision>
    <inertial>
      <mass value="0.15"/>
      <inertia ixx="0.000025" ixy="0" ixz="0" iyy="0.000025" iyz="0" izz="0.000025"/>
    </inertial>
  </link>
  <joint name="toe_hr_joint" type="fixed">
    <parent link="shank_hr"/>
    <child link="toe_hr"/>
    <origin xyz="0 0 -0.28"/>
    <limit effort="100" velocity="100"/>
    <joint_properties damping="0.0" friction="0.0"/>
  </joint>


<!--!!!!!!!!!!!! Hind Left Leg !!!!!!!!!!!!!!!!!!!!!!!!!!!!!!!!!!!!-->
    <joint name="motor_hip_backL_j" type="continuous">
        <axis xyz="1 0 0"/>
        <origin rpy="0 0 0" xyz="-0.214 0.0725 0.0"/>
        <parent link="body"/>
        <child link="abduct_hl"/>
        <limit effort="100" velocity="100"/>
        <joint_properties damping="0.0" friction="0.0"/>
    </joint>
    <link name="abduct_hl">
        <inertial>
            <mass value="0.56"/>
            <origin xyz="0.0 0.036 0."/>
            <inertia ixx="0.000381" ixy="0.000058" ixz="0.00000045"
                iyy="0.000560" iyz="0.00000095" izz="0.000444"/>
        </inertial>
        <visual>
            <geometry>
                <mesh filename="meshes/abad.stl"/>
            </geometry>
            <material name="y">
                <color rgba="1. 0.84313725 0. 1"/>
            </material>
            <origin rpy="0 0.0 3.14159" xyz="0 0.0 0.0"/>
        </visual>
        <collision>
            <geometry>
                <mesh filename="meshes/abad.stl"/>
            </geometry>
            <origin rpy="0 0 3.14159" xyz="0 0 0"/>
        </collision>
    </link>

    <joint name="motor_upper_backL_j" type="continuous">
        <axis xyz="0 1 0"/>
        <origin rpy="0.0 0.0 0.0" xyz="0.0 0.088 0.00"/>
        <parent link="abduct_hl"/>
        <child link="thigh_hl"/>
        <limit effort="100" velocity="100"/>
        <joint_properties damping="0.0" friction="0.0"/>
    </joint>
    <link name="thigh_hl">
        <inertial>
            <mass value="0.634"/>
            <origin xyz="0.0 0.016 -0.02"/>
            <inertia ixx="0.001983" ixy="0.000245" ixz="0.000013"
                iyy="0.002103" iyz="0.0000015" izz="0.000408"/>
        </inertial>
        <visual>
            <geometry>
                <mesh filename="meshes/upperleg.stl"/>
            </geometry>
            <material name="y">
                <color rgba="1. 0.84313725 0. 1"/>
            </material>
            <origin rpy="0.0 0 3.14159" xyz="0.0 0.0 0.0"/>
        </visual>
        <collision>
            <geometry>
                <mesh filename="meshes/upperleg.stl"/>
            </geometry>
            <origin rpy="0 0 3.14159" xyz="0 0 0"/>
        </collision>
    </link>

    <joint name="motor_lower_backL_j" type="continuous">
        <axis xyz="0 1 0"/>
        <origin rpy="0.0 0 0.0" xyz="0.0 0.0 -0.3"/>
        <parent link="thigh_hl"/>
        <child link="shank_hl"/>
        <limit effort="100" velocity="100"/>
        <joint_properties damping="0.0" friction="0.0"/>
    </joint>
    <link name="shank_hl">
        <inertial>
            <mass value="0.064"/>
            <origin xyz="0.0 0.0 -0.3"/>
            <inertia ixx="0.000245" ixy="0" ixz="0.0" iyy="0.000248" iyz="0" izz="0.000006"/>
        </inertial>
        <visual>
            <geometry>
                <mesh filename="meshes/lowerleg.stl"/>
            </geometry>
            <material name="g">
                <color rgba="0.54509804 0.54509804 0.47843137 1"/>
            </material>
            <origin rpy="0.0 0.0 3.141592" xyz="0.0 0.0 0.0"/>
        </visual>
        <collision>
            <geometry>
                <mesh filename="meshes/lowerleg.stl"/>
            </geometry>
            <origin rpy="0 0 3.141592" xyz="0 0 0"/>
        </collision>
    </link>
    <link name="toe_hl">
      <contact>
      <friction_anchor/>
      <stiffness value="30000.0"/>
      <damping value="1000.0"/>
      <spinning_friction value="0.3"/>
      <lateral_friction value="3.0"/>
    </contact>
    <visual>
      <origin rpy="0 0 0" xyz="0 0 0"/>
      <geometry>
        <sphere radius="0.015"/>
      </geometry>
        <material name="black">
                <color rgba="1 1 1 1"/>
        </material>
      <material name="darkgray"/>
    </visual>
    <collision>
      <origin rpy="0 0 0" xyz="0 0 0"/>
      <geometry>
        <sphere radius="0.015"/>
      </geometry>
    </collision>
    <inertial>
      <mass value="0.15"/>
      <inertia ixx="0.000025" ixy="0" ixz="0" iyy="0.000025" iyz="0" izz="0.000025"/>
    </inertial>
  </link>
  <joint name="toe_hl_joint" type="fixed">
    <parent link="shank_hl"/>
    <child link="toe_hl"/>
    <origin xyz="0 0 -0.28"/>
    <limit effort="100" velocity="100"/>
    <joint_properties damping="0.0" friction="0.0"/>
  </joint>



</robot>
