<?xml version="1.0" ?>
<robot name="a1_description" xmlns:xacro="http://www.ros.org/wiki/xacro">

    <material name="black">
        <color rgba="0.0 0.0 0.0 1.0"/>
    </material>
    <material name="blue">
        <color rgba="0.0 0.0 0.8 1.0"/>
    </material>
    <material name="green">
        <color rgba="0.0 0.8 0.0 1.0"/>
    </material>
    <material name="grey">
        <color rgba="0.2 0.2 0.2 1.0"/>
    </material>
    <material name="silver">
        <color rgba="0.913725490196 0.913725490196 0.847058823529 1.0"/>
    </material>
    <material name="orange">
        <color rgba="1.0 0.423529411765 0.0392156862745 1.0"/>
    </material>
    <material name="brown">
        <color rgba="0.870588235294 0.811764705882 0.764705882353 1.0"/>
    </material>
    <material name="red">
        <color rgba="0.8 0.0 0.0 1.0"/>
    </material>
    <material name="white">
        <color rgba="1.0 1.0 1.0 1.0"/>
    </material>
    <material name="yellow">
        <color rgba="0.8 0.5 0 1.0"/>
    </material>

    <link name="base">
        <visual>
            <origin rpy="0 0 0" xyz="0 0 0"/>
            <geometry>
                <mesh filename="meshes/base.obj" scale="1 1 1"/>
            </geometry>
            <material name="yellow"/>
        </visual>

        <collision>
            <origin rpy="0 0 0" xyz="0 0 0"/>
            <geometry>
                <mesh filename="meshes/base.obj"/>
            </geometry>
        </collision>

        <inertial>
            <origin rpy="0 0 0" xyz="0 0 0"/>
            <mass value="10"/>
            <inertia ixx="0.0973333" ixy="0" ixz="0" iyy="1.02467" iyz="0" izz="1.04493"/>
        </inertial>
    </link>

    <!--!!!!!!!!!!!! Front Right Leg !!!!!!!!!!!!!!!!!!!!!!!!!!!!!!!!!!!!-->

    <joint name="FR_hip_joint" type="revolute">
        <origin rpy="0 0 0" xyz="0.29785 -0.055 0"/>
        <parent link="base"/>
        <child link="FR_hip"/>
        <axis xyz="1 0 0"/>
        <dynamics damping="0" friction="0"/>
        <limit effort="80" lower="-0.785398" upper="0.785398" velocity="15"/>
    </joint>

    <link name="FR_hip">
        <visual>
            <origin rpy="0 0 0" xyz="0 0 0"/>
            <geometry>
                <mesh filename="meshes/front_right_hip.obj" scale="1 1 1"/>
            </geometry>
            <material name="grey"/>
        </visual>

        <collision>
            <origin rpy="0 0 0" xyz="0 0 0"/>
            <geometry>
                <mesh filename="meshes/front_right_hip.obj"/>
            </geometry>
        </collision>

        <inertial>
            <origin rpy="0 0 0" xyz="0 0 0"/>
            <mass value="2"/>
            <inertia ixx="0.0027" ixy="0" ixz="0" iyy="0.00416667" iyz="0" izz="0.00416667"/>
        </inertial>
    </link>

    <joint name="FR_upper_joint" type="revolute">
        <origin rpy="0 0 0" xyz="0 -0.110945 0"/>
        <parent link="FR_hip"/>
        <child link="FR_upper"/>
        <axis xyz="0 1 0"/>
        <dynamics damping="0" friction="0"/>
        <limit effort="80" lower="-0.898845" upper="2.29511" velocity="15"/>
    </joint>

    <link name="FR_upper">
        <visual>
            <origin rpy="0 0 0" xyz="0 0 0"/>
            <geometry>
                <mesh filename="meshes/front_right_upper_leg.obj" scale="1 1 1"/>
            </geometry>
            <material name="yellow"/>
        </visual>

        <collision>
            <origin rpy="0 0 0" xyz="0 0 0"/>
            <geometry>
                <mesh filename="meshes/front_right_upper_leg.obj" scale="1 1 1"/>
            </geometry>
        </collision>

        <inertial>
            <origin rpy="0 0 0" xyz="0 0 -0.14"/>
            <mass value="1.0"/>
            <inertia ixx="0.0155334" ixy="0" ixz="0" iyy="0.0155334" iyz="0" izz="0.000962667"/>
        </inertial>
    </link>

    <joint name="FR_lower_joint" type="revolute">
        <origin rpy="0 0 0" xyz="0.025 0 -0.3205"/>
        <parent link="FR_upper"/>
        <child link="FR_lower"/>
        <axis xyz="0 1 0"/>
        <dynamics damping="0" friction="0"/>
        <limit effort="80" lower="-2.7929" upper="-0.254801" velocity="15"/>
    </joint>

    <link name="FR_lower">
        <visual>
            <origin rpy="0 0 0" xyz="0 0 0"/>
            <geometry>
                <mesh filename="meshes/front_right_lower_leg.obj" scale="1 1 1"/>
            </geometry>
            <material name="grey"/>
        </visual>

        <collision>
            <origin rpy="0 0 0" xyz="0 0 0"/>
            <geometry>
                <mesh filename="meshes/front_right_lower_leg.obj" scale="1 1 1"/>
            </geometry>
        </collision>

        <inertial>
            <origin rpy="0 0 0" xyz="0 0 -0.16"/>
            <mass value="0.5"/>
            <inertia ixx="0.00743438" ixy="0" ixz="0" iyy="0.00740104" iyz="0" izz="0.000135417"/>
        </inertial>
    </link>

    <joint name="FR_toe_fixed" type="fixed">
        <origin rpy="0 0 0" xyz="0 0 -0.36"/>
        <parent link="FR_lower"/>
        <child link="FR_toe"/>
    </joint>

    <link name="FR_toe">
        <visual>
            <origin rpy="0 0 0" xyz="0 0 0"/>
            <geometry>
                <sphere radius="0.01"/>
            </geometry>
            <material name="orange"/>
        </visual>

        <collision>
            <origin rpy="0 0 0" xyz="0 0 0"/>
            <geometry>
                <sphere radius="0.02"/>
            </geometry>
        </collision>

        <inertial>
            <mass value="0.06"/>
            <inertia ixx="9.6e-06" ixy="0.0" ixz="0.0" iyy="9.6e-06" iyz="0.0" izz="9.6e-06"/>
        </inertial>
    </link>

<!--!!!!!!!!!!!! Front Left Leg !!!!!!!!!!!!!!!!!!!!!!!!!!!!!!!!!!!!-->
  <joint name="FL_hip_joint" type="revolute">
    <origin rpy="0 0 0" xyz="0.29785 0.055 0"/>
    <parent link="base"/>
    <child link="FL_hip"/>
    <axis xyz="1 0 0"/>
    <dynamics damping="0" friction="0"/>
    <limit effort="80" lower="-0.785398" upper="0.785398" velocity="15"/>
  </joint>

  <link name="FL_hip">
    <visual>
      <origin rpy="0 0 0" xyz="0 0 0"/>
      <geometry>
        <mesh filename="meshes/front_left_hip.obj" scale="1 1 1"/>
      </geometry>
      <material name="grey"/>
    </visual>

    <collision>
      <origin rpy="0 0 0" xyz="0 0 0"/>
      <geometry>
        <mesh filename="meshes/front_left_hip.obj" scale="1 1 1"/>
      </geometry>
    </collision>

    <inertial>
      <origin rpy="0 0 0" xyz="0 0 0"/>
      <mass value="2"/>
      <inertia ixx="0.0027" ixy="0" ixz="0" iyy="0.00416667" iyz="0" izz="0.00416667"/>
    </inertial>
  </link>

  <joint name="FL_upper_joint" type="revolute">
    <origin rpy="0 0 0" xyz="0 0.110945 0"/>
    <parent link="FL_hip"/>
    <child link="FL_upper"/>
    <axis xyz="0 1 0"/>
    <dynamics damping="0" friction="0"/>
    <limit effort="80" lower="-0.898845" upper="2.29511" velocity="15"/>
  </joint>

  <link name="FL_upper">
    <visual>
      <origin rpy="0 0 0" xyz="0 0 0"/>
      <geometry>
        <mesh filename="meshes/front_left_upper_leg.obj" scale="1 1 1"/>
      </geometry>
      <material name="yellow"/>
    </visual>

    <collision>
      <origin rpy="0 0 0" xyz="0 0 0"/>
      <geometry>
        <mesh filename="meshes/front_left_upper_leg.obj" scale="1 1 1"/>
      </geometry>
    </collision>

    <inertial>
      <origin rpy="0 0 0" xyz="0 0 -0.14"/>
      <mass value="1"/>
      <inertia ixx="0.0155334" ixy="0" ixz="09" iyy="0.0155334" iyz="0" izz="0.000962667"/>
    </inertial>
  </link>

  <joint name="FL_lower_joint" type="revolute">
    <origin rpy="0 0 0" xyz="0.025 0 -0.3205"/>
    <parent link="FL_upper"/>
    <child link="FL_lower"/>
    <axis xyz="0 1 0"/>
    <dynamics damping="0" friction="0"/>
    <limit effort="80" lower="-2.7929 " upper="-0.254801" velocity="15"/>
  </joint>

  <link name="FL_lower">
    <visual>
      <origin rpy="0 0 0" xyz="0 0 0"/>
      <geometry>
        <mesh filename="meshes/front_left_lower_leg.obj" scale="1 1 1"/>
      </geometry>
      <material name="grey"/>
    </visual>
    <collision>
      <origin rpy="0 0 0" xyz="0 0 0"/>
      <geometry>
        <mesh filename="meshes/front_left_lower_leg.obj" scale="1 1 1"/>
      </geometry>
    </collision>

    <inertial>
      <origin rpy="0 0 0" xyz="0 0 -0.16"/>
      <mass value="0.5"/>
      <inertia ixx="0.00743438" ixy="0.0" ixz="0" iyy="0.00740104" iyz="0.0" izz="0.000135417"/>
    </inertial>
  </link>

  <joint name="FL_toe_fixed" type="fixed">
    <origin rpy="0 0 0" xyz="0 0 -0.36"/>
    <parent link="FL_lower"/>
    <child link="FL_toe"/>
  </joint>

  <link name="FL_toe">
    <visual>
      <origin rpy="0 0 0" xyz="0 0 0"/>
      <geometry>
        <sphere radius="0.01"/>
      </geometry>
      <material name="orange"/>
    </visual>
    <collision>
      <origin rpy="0 0 0" xyz="0 0 0"/>
      <geometry>
        <sphere radius="0.02"/>
      </geometry>
    </collision>
    <inertial>
      <mass value="0.06"/>
      <inertia ixx="9.6e-06" ixy="0.0" ixz="0.0" iyy="9.6e-06" iyz="0.0" izz="9.6e-06"/>
    </inertial>
  </link>

  <!--!!!!!!!!!!!! Back Right Leg !!!!!!!!!!!!!!!!!!!!!!!!!!!!!!!!!!!!-->
  <joint name="RR_hip_joint" type="revolute">
    <origin rpy="0 0 0" xyz="-0.29785 -0.055 0 0"/>
    <parent link="base"/>
    <child link="RR_hip"/>
    <axis xyz="1 0 0"/>
    <dynamics damping="0" friction="0"/>
    <limit effort="80" lower="-0.785398" upper="0.785398" velocity="15"/>
  </joint>

  <link name="RR_hip">
    <visual>
      <origin rpy="0 0 0" xyz="0 0 0"/>
      <geometry>
        <mesh filename="meshes/rear_right_hip.obj" scale="1 1 1"/>
      </geometry>
      <material name="grey"/>
    </visual>

    <collision>
      <origin rpy="0 0 0" xyz="0 0 0"/>
      <geometry>
        <mesh filename="meshes/rear_right_hip.obj" scale="1 1 1"/>
      </geometry>
    </collision>

    <inertial>
      <origin rpy="0 0 0" xyz="0 0 0"/>
      <mass value="2"/>
      <inertia ixx="0.0027" ixy="0" ixz="0" iyy="0.00416667" iyz="0" izz="0.00416667"/>
    </inertial>
  </link>

  <joint name="RR_upper_joint" type="revolute">
    <origin rpy="0 0 0" xyz="0 -0.110945 0"/>
    <parent link="RR_hip"/>
    <child link="RR_upper"/>
    <axis xyz="0 1 0"/>
    <dynamics damping="0" friction="0"/>
    <limit effort="80" lower="-0.898845" upper="2.29511" velocity="15"/>
  </joint>

  <link name="RR_upper">
    <visual>
      <origin rpy="0 0 0" xyz="0 0 0"/>
      <geometry>
        <mesh filename="meshes/rear_right_upper_leg.obj" scale="1 1 1"/>
      </geometry>
      <material name="yellow"/>
    </visual>

    <collision>
      <origin rpy="0 0 0" xyz="0 0 0"/>
      <geometry>
        <mesh filename="meshes/rear_right_upper_leg.obj" scale="1 1 1"/>
      </geometry>
    </collision>

    <inertial>
      <origin rpy="0 0 0" xyz="0 0 -0.14"/>
      <mass value="1"/>
      <inertia ixx="0.0155334" ixy="0" ixz="0" iyy="0.0155334" iyz="0" izz="0.000962667"/>
    </inertial>
  </link>

  <joint name="RR_lower_joint" type="revolute">
    <origin rpy="0 0 0" xyz="0.025 0 -0.3205"/>
    <parent link="RR_upper"/>
    <child link="RR_lower"/>
    <axis xyz="0 1 0"/>
    <dynamics damping="0" friction="0"/>
    <limit effort="80" lower="-2.7929" upper="-0.254801" velocity="15"/>
  </joint>

  <link name="RR_lower">
    <visual>
      <origin rpy="0 0 0" xyz="0 0 0"/>
      <geometry>
        <mesh filename="meshes/rear_right_lower_leg.obj" scale="1 1 1"/>
      </geometry>
      <material name="grey"/>
    </visual>
    <collision>
      <origin rpy="0 0 0" xyz="0 0 0"/>
      <geometry>
        <mesh filename="meshes/rear_right_lower_leg.obj" scale="1 1 1"/>
      </geometry>
    </collision>

    <inertial>
      <origin rpy="0 0 0" xyz="0 0 -0.16"/>
      <mass value="0.5"/>
      <inertia ixx="0.00743438" ixy="0.0" ixz="0" iyy="0.00740104" iyz="0.0" izz="0.000135417"/>
    </inertial>
  </link>

  <joint name="RR_toe_fixed" type="fixed">
    <origin rpy="0 0 0" xyz="0 0 -0.36"/>
    <parent link="RR_lower"/>
    <child link="RR_toe"/>
  </joint>

  <link name="RR_toe">
    <visual>
      <origin rpy="0 0 0" xyz="0 0 0"/>
      <geometry>
        <sphere radius="0.01"/>
      </geometry>
      <material name="orange"/>
    </visual>
    <collision>
      <origin rpy="0 0 0" xyz="0 0 0"/>
      <geometry>
        <sphere radius="0.02"/>
      </geometry>
    </collision>
    <inertial>
      <mass value="0.06"/>
      <inertia ixx="9.6e-06" ixy="0.0" ixz="0.0" iyy="9.6e-06" iyz="0.0" izz="9.6e-06"/>
    </inertial>
  </link>

  <!--!!!!!!!!!!!! Back Left Leg !!!!!!!!!!!!!!!!!!!!!!!!!!!!!!!!!!!!-->
  <joint name="RL_hip_joint" type="revolute">
    <origin rpy="0 0 0" xyz="-0.29785 0.055 0"/>
    <parent link="base"/>
    <child link="RL_hip"/>
    <axis xyz="1 0 0"/>
    <dynamics damping="0" friction="0"/>
    <limit effort="80" lower="-0.785398" upper="0.785398" velocity="15"/>
  </joint>

  <link name="RL_hip">
    <visual>
      <origin rpy="0 0 0" xyz="0 0 0"/>
      <geometry>
        <mesh filename="meshes/rear_left_hip.obj" scale="1 1 1"/>
      </geometry>
      <material name="grey"/>
    </visual>

    <collision>
      <origin rpy="0 0 0" xyz="0 0 0"/>
      <geometry>
        <mesh filename="meshes/rear_left_hip.obj" scale="1 1 1"/>
      </geometry>
    </collision>

    <inertial>
      <origin rpy="0 0 0" xyz="0 0 0"/>
      <mass value="2.0"/>
      <inertia ixx="0.0027" ixy="0" ixz="0" iyy="0.00416667" iyz="0" izz="0.00416667"/>
    </inertial>
  </link>

  <joint name="RL_upper_joint" type="revolute">
    <origin rpy="0 0 0" xyz="0 0.110945 0"/>
    <parent link="RL_hip"/>
    <child link="RL_upper"/>
    <axis xyz="0 1 0"/>
    <dynamics damping="0" friction="0"/>
    <limit effort="80" lower="-0.898845" upper="2.29511" velocity="15"/>
  </joint>

  <link name="RL_upper">
    <visual>
      <origin rpy="0 0 0" xyz="0 0 0"/>
      <geometry>
        <mesh filename="meshes/rear_left_upper_leg.obj" scale="1 1 1"/>
      </geometry>
      <material name="yellow"/>
    </visual>

    <collision>
      <origin rpy="0 0 0" xyz="0 0 0"/>
      <geometry>
        <mesh filename="meshes/rear_left_upper_leg.obj" scale="1 1 1"/>
      </geometry>
    </collision>

    <inertial>
      <origin rpy="0 0 0" xyz="0 0 -0.14"/>
      <mass value="1"/>
      <inertia ixx="0.0155334" ixy="0" ixz="0" iyy="0.0155334" iyz="0" izz="0.000962667"/>
    </inertial>
  </link>

  <joint name="RL_lower_joint" type="revolute">
    <origin rpy="0 0 0" xyz="0.025 0 -0.3205"/>
    <parent link="RL_upper"/>
    <child link="RL_lower"/>
    <axis xyz="0 1 0"/>
    <dynamics damping="0" friction="0"/>
    <limit effort="80" lower="-2.7929" upper="-0.254801" velocity="15"/>
  </joint>

  <link name="RL_lower">
    <visual>
      <origin rpy="0 0 0" xyz="0 0 0"/>
      <geometry>
        <mesh filename="meshes/rear_left_lower_leg.obj" scale="1 1 1"/>
      </geometry>
      <material name="grey"/>
    </visual>

    <collision>
      <origin rpy="0 0 0" xyz="0 0 0"/>
      <geometry>
        <mesh filename="meshes/rear_left_lower_leg.obj" scale="1 1 1"/>
      </geometry>
    </collision>

    <inertial>
      <origin rpy="0 0 0" xyz="0 0 -0.16"/>
      <mass value="0.5"/>
      <inertia ixx="0.00743438" ixy="0.0" ixz="0" iyy="0.00740104" iyz="0.0" izz="0.000135417"/>
    </inertial>
  </link>

  <joint name="RL_toe_fixed" type="fixed">
    <origin rpy="0 0 0" xyz="0 0 -0.36"/>
    <parent link="RL_lower"/>
    <child link="RL_toe"/>
  </joint>

  <link name="RL_toe">
    <visual>
      <origin rpy="0 0 0" xyz="0 0 0"/>
      <geometry>
        <sphere radius="0.01"/>
      </geometry>
      <material name="orange"/>
    </visual>
    <collision>
      <origin rpy="0 0 0" xyz="0 0 0"/>
      <geometry>
        <sphere radius="0.02"/>
      </geometry>
    </collision>
    <inertial>
      <mass value="0.06"/>
      <inertia ixx="9.6e-06" ixy="0.0" ixz="0.0" iyy="9.6e-06" iyz="0.0" izz="9.6e-06"/>
    </inertial>
  </link>

</robot>